<sdf version='1.7'>
  <model name='rov'>
    <link name='base_link'>
      <inertial>
        <pose>0.001131 0.137118 -0.022535 0 -0 0</pose>
        <mass>5.7776</mass>
        <inertia>
          <ixx>0.173897</ixx>
          <ixy>0.00230966</ixy>
          <ixz>0.000631713</ixz>
          <iyy>0.156411</iyy>
          <iyz>-0.0012762</iyz>
          <izz>0.26283</izz>
        </inertia>
      </inertial>
      <collision name='base_link_fixed_joint_lump__MEH_Crossbar_collision'>
        <pose>0 0 0 0 -0 0</pose>
        <geometry>
          <box>
            <size>0.37 0.015 0.015</size>
          </box>
        </geometry>
      </collision>
      <collision name='base_link_fixed_joint_lump__HGripper_Post_collision_1'>
        <pose>0.0925 -0.075 -0.125 0 -0 0</pose>
        <geometry>
          <box>
            <size>0.015 0.12 0.015</size>
          </box>
        </geometry>
      </collision>
      <collision name='base_link_fixed_joint_lump__HGripper_Crossbar_collision_2'>
        <pose>0.0925 -0.14 -0.125 0 -0 0</pose>
        <geometry>
          <box>
            <size>0.15 0.015 0.015</size>
          </box>
        </geometry>
      </collision>
      <collision name='base_link_fixed_joint_lump__HGripper_Finger_Static_collision_3'>
        <pose>0.0175 -0.19 -0.125 0 -0 0</pose>
        <geometry>
          <box>
            <size>0.015 0.1 0.015</size>
          </box>
        </geometry>
      </collision>
      <collision name='base_link_fixed_joint_lump__Upper_Left_Crossbar_collision_4'>
        <pose>-0.185 0.12 0 0 -0 0</pose>
        <geometry>
          <box>
            <size>0.015 0.41 0.015</size>
          </box>
        </geometry>
      </collision>
      <collision name='base_link_fixed_joint_lump__Upper_Back_Crossbar_collision_5'>
        <pose>0 0.33 0 0 -0 0</pose>
        <geometry>
          <box>
            <size>0.37 0.015 0.015</size>
          </box>
        </geometry>
      </collision>
      <collision name='base_link_fixed_joint_lump__PSE_collision_6'>
        <pose>0 0.27 0.024 0 -0 0</pose>
        <geometry>
          <box>
            <size>0.17 0.12 0.055</size>
          </box>
        </geometry>
      </collision>
      <collision name='base_link_fixed_joint_lump__VGripper_Post_collision_7'>
        <pose>0 0.21 -0.03 0 -0 0</pose>
        <geometry>
          <box>
            <size>0.015 0.015 0.12</size>
          </box>
        </geometry>
      </collision>
      <collision name='base_link_fixed_joint_lump__VGripper_Crossbar_collision_8'>
        <pose>0 0.21 -0.09 0 -0 0</pose>
        <geometry>
          <box>
            <size>0.15 0.015 0.015</size>
          </box>
        </geometry>
      </collision>
      <collision name='base_link_fixed_joint_lump__VGripper_Finger_Static_collision_9'>
        <pose>-0.075 0.21 -0.14 0 -0 0</pose>
        <geometry>
          <box>
            <size>0.015 0.015 0.1</size>
          </box>
        </geometry>
      </collision>
      <collision name='base_link_fixed_joint_lump__SB_Left_collision_10'>
        <pose>-0.148 0.205108 0.045298 -1.57319 0 0</pose>
        <geometry>
          <cylinder>
            <length>0.2</length>
            <radius>0.055</radius>
          </cylinder>
        </geometry>
      </collision>
      <collision name='base_link_fixed_joint_lump__SB_Right_collision_11'>
        <pose>0.148 0.205108 0.045298 -1.57319 0 0</pose>
        <geometry>
          <cylinder>
            <length>0.2</length>
            <radius>0.055</radius>
          </cylinder>
        </geometry>
      </collision>
      <collision name='base_link_fixed_joint_lump__Back_Left_Post_collision_12'>
        <pose>-0.074 0.33 -0.1 0 -0 0</pose>
        <geometry>
          <box>
            <size>0.015 0.015 0.2</size>
          </box>
        </geometry>
      </collision>
      <collision name='base_link_fixed_joint_lump__Back_Right_Post_collision_13'>
        <pose>0.074 0.33 -0.1 0 -0 0</pose>
        <geometry>
          <box>
            <size>0.015 0.015 0.2</size>
          </box>
        </geometry>
      </collision>
      <collision name='base_link_fixed_joint_lump__Left_Post_collision_14'>
        <pose>-0.185 0 -0.1 0 -0 0</pose>
        <geometry>
          <box>
            <size>0.015 0.015 0.2</size>
          </box>
        </geometry>
      </collision>
      <collision name='base_link_fixed_joint_lump__Lower_Front_Crossbar_collision_15'>
        <pose>0 0 -0.2 0 -0 0</pose>
        <geometry>
          <box>
            <size>0.37 0.015 0.015</size>
          </box>
        </geometry>
      </collision>
      <collision name='base_link_fixed_joint_lump__Lower_Left_Crossbar_collision_16'>
        <pose>-0.185 0.12 -0.2 0 -0 0</pose>
        <geometry>
          <box>
            <size>0.015 0.41 0.015</size>
          </box>
        </geometry>
      </collision>
      <collision name='base_link_fixed_joint_lump__Lower_Back_Crossbar_collision_17'>
        <pose>0 0.33 -0.2 0 -0 0</pose>
        <geometry>
          <box>
            <size>0.37 0.015 0.015</size>
          </box>
        </geometry>
      </collision>
      <collision name='base_link_fixed_joint_lump__Lower_Right_Crossbar_collision_18'>
        <pose>0.185 0.12 -0.2 0 -0 0</pose>
        <geometry>
          <box>
            <size>0.015 0.41 0.015</size>
          </box>
        </geometry>
      </collision>
      <collision name='base_link_fixed_joint_lump__Thruster_Back_Left_collision_19'>
        <pose>-0.185 0.33 -0.045 1.57 -0 0.77</pose>
        <geometry>
          <cylinder>
            <length>0.05</length>
            <radius>0.045</radius>
          </cylinder>
        </geometry>
      </collision>
      <collision name='base_link_fixed_joint_lump__Thruster_Front_Left_collision_20'>
        <pose>-0.185 -0.06 -0.045 1.57 -0 0.77</pose>
        <geometry>
          <cylinder>
            <length>0.05</length>
            <radius>0.045</radius>
          </cylinder>
        </geometry>
      </collision>
      <collision name='base_link_fixed_joint_lump__Thruster_Vert_Left_collision_21'>
        <pose>-0.23 0.13 0 0 -0 0</pose>
        <geometry>
          <cylinder>
            <length>0.05</length>
            <radius>0.045</radius>
          </cylinder>
        </geometry>
      </collision>
      <collision name='base_link_fixed_joint_lump__Upper_Right_Crossbar_collision_22'>
        <pose>0.185 0.12 0 0 -0 0</pose>
        <geometry>
          <box>
            <size>0.015 0.41 0.015</size>
          </box>
        </geometry>
      </collision>
      <collision name='base_link_fixed_joint_lump__Thruster_Vert_Right_collision_23'>
        <pose>0.23 0.13 0 0 -0 0</pose>
        <geometry>
          <cylinder>
            <length>0.05</length>
            <radius>0.045</radius>
          </cylinder>
        </geometry>
      </collision>
      <collision name='base_link_fixed_joint_lump__Right_Post_collision_24'>
        <pose>0.185 0 -0.1 0 -0 0</pose>
        <geometry>
          <box>
            <size>0.015 0.015 0.2</size>
          </box>
        </geometry>
      </collision>
      <collision name='base_link_fixed_joint_lump__Thruster_Back_Right_collision_25'>
        <pose>0.185 0.33 -0.045 1.57 -0 0.77</pose>
        <geometry>
          <cylinder>
            <length>0.05</length>
            <radius>0.045</radius>
          </cylinder>
        </geometry>
      </collision>
      <collision name='base_link_fixed_joint_lump__Thruster_Front_Right_collision_26'>
        <pose>0.185 -0.06 -0.045 1.57 -0 0.77</pose>
        <geometry>
          <cylinder>
            <length>0.05</length>
            <radius>0.045</radius>
          </cylinder>
        </geometry>
      </collision>
      <collision name='base_link_fixed_joint_lump__MEH_collision_27'>
        <pose>0 -0.055 0.04 0 -0 0</pose>
        <geometry>
          <box>
            <size>0.16 0.11 0.16</size>
          </box>
        </geometry>
      </collision>
      <visual name='base_link_fixed_joint_lump__MEH_Crossbar_visual'>
        <pose>0 0 0 0 -0 0</pose>
        <geometry>
          <box>
            <size>0.37 0.015 0.015</size>
          </box>
        </geometry>
      </visual>
      <visual name='base_link_fixed_joint_lump__HGripper_Post_visual_1'>
        <pose>0.0925 -0.075 -0.125 0 -0 0</pose>
        <geometry>
          <box>
            <size>0.015 0.12 0.015</size>
          </box>
        </geometry>
      </visual>
      <visual name='base_link_fixed_joint_lump__HGripper_Crossbar_visual_2'>
        <pose>0.0925 -0.14 -0.125 0 -0 0</pose>
        <geometry>
          <box>
            <size>0.15 0.015 0.015</size>
          </box>
        </geometry>
      </visual>
      <visual name='base_link_fixed_joint_lump__HGripper_Finger_Static_visual_3'>
        <pose>0.0175 -0.19 -0.125 0 -0 0</pose>
        <geometry>
          <box>
            <size>0.015 0.1 0.015</size>
          </box>
        </geometry>
      </visual>
      <visual name='base_link_fixed_joint_lump__Upper_Left_Crossbar_visual_4'>
        <pose>-0.185 0.12 0 0 -0 0</pose>
        <geometry>
          <box>
            <size>0.015 0.41 0.015</size>
          </box>
        </geometry>
      </visual>
      <visual name='base_link_fixed_joint_lump__Upper_Back_Crossbar_visual_5'>
        <pose>0 0.33 0 0 -0 0</pose>
        <geometry>
          <box>
            <size>0.37 0.015 0.015</size>
          </box>
        </geometry>
      </visual>
      <visual name='base_link_fixed_joint_lump__PSE_visual_6'>
        <pose>0 0.27 0.024 0 -0 0</pose>
        <geometry>
          <box>
            <size>0.17 0.12 0.055</size>
          </box>
        </geometry>
      </visual>
      <visual name='base_link_fixed_joint_lump__VGripper_Post_visual_7'>
        <pose>0 0.21 -0.03 0 -0 0</pose>
        <geometry>
          <box>
            <size>0.015 0.015 0.12</size>
          </box>
        </geometry>
      </visual>
      <visual name='base_link_fixed_joint_lump__VGripper_Crossbar_visual_8'>
        <pose>0 0.21 -0.09 0 -0 0</pose>
        <geometry>
          <box>
            <size>0.15 0.015 0.015</size>
          </box>
        </geometry>
      </visual>
      <visual name='base_link_fixed_joint_lump__VGripper_Finger_Static_visual_9'>
        <pose>-0.075 0.21 -0.14 0 -0 0</pose>
        <geometry>
          <box>
            <size>0.015 0.015 0.1</size>
          </box>
        </geometry>
      </visual>
      <visual name='base_link_fixed_joint_lump__SB_Left_visual_10'>
        <pose>-0.148 0.205108 0.045298 -1.57319 0 0</pose>
        <geometry>
          <cylinder>
            <length>0.2</length>
            <radius>0.055</radius>
          </cylinder>
        </geometry>
      </visual>
      <visual name='base_link_fixed_joint_lump__SB_Right_visual_11'>
        <pose>0.148 0.205108 0.045298 -1.57319 0 0</pose>
        <geometry>
          <cylinder>
            <length>0.2</length>
            <radius>0.055</radius>
          </cylinder>
        </geometry>
      </visual>
      <visual name='base_link_fixed_joint_lump__Back_Left_Post_visual_12'>
        <pose>-0.074 0.33 -0.1 0 -0 0</pose>
        <geometry>
          <box>
            <size>0.015 0.015 0.2</size>
          </box>
        </geometry>
      </visual>
      <visual name='base_link_fixed_joint_lump__Back_Right_Post_visual_13'>
        <pose>0.074 0.33 -0.1 0 -0 0</pose>
        <geometry>
          <box>
            <size>0.015 0.015 0.2</size>
          </box>
        </geometry>
      </visual>
      <visual name='base_link_fixed_joint_lump__Left_Post_visual_14'>
        <pose>-0.185 0 -0.1 0 -0 0</pose>
        <geometry>
          <box>
            <size>0.015 0.015 0.2</size>
          </box>
        </geometry>
      </visual>
      <visual name='base_link_fixed_joint_lump__Lower_Front_Crossbar_visual_15'>
        <pose>0 0 -0.2 0 -0 0</pose>
        <geometry>
          <box>
            <size>0.37 0.015 0.015</size>
          </box>
        </geometry>
      </visual>
      <visual name='base_link_fixed_joint_lump__Lower_Left_Crossbar_visual_16'>
        <pose>-0.185 0.12 -0.2 0 -0 0</pose>
        <geometry>
          <box>
            <size>0.015 0.41 0.015</size>
          </box>
        </geometry>
      </visual>
      <visual name='base_link_fixed_joint_lump__Lower_Back_Crossbar_visual_17'>
        <pose>0 0.33 -0.2 0 -0 0</pose>
        <geometry>
          <box>
            <size>0.37 0.015 0.015</size>
          </box>
        </geometry>
      </visual>
      <visual name='base_link_fixed_joint_lump__Lower_Right_Crossbar_visual_18'>
        <pose>0.185 0.12 -0.2 0 -0 0</pose>
        <geometry>
          <box>
            <size>0.015 0.41 0.015</size>
          </box>
        </geometry>
      </visual>
      <visual name='base_link_fixed_joint_lump__Thruster_Back_Left_visual_19'>
        <pose>-0.185 0.33 -0.045 1.57 -0 0.77</pose>
        <geometry>
          <cylinder>
            <length>0.05</length>
            <radius>0.045</radius>
          </cylinder>
        </geometry>
      </visual>
      <visual name='base_link_fixed_joint_lump__Thruster_Front_Left_visual_20'>
        <pose>-0.185 -0.06 -0.045 1.57 -0 0.77</pose>
        <geometry>
          <cylinder>
            <length>0.05</length>
            <radius>0.045</radius>
          </cylinder>
        </geometry>
      </visual>
      <visual name='base_link_fixed_joint_lump__Thruster_Vert_Left_visual_21'>
        <pose>-0.23 0.13 0 0 -0 0</pose>
        <geometry>
          <cylinder>
            <length>0.05</length>
            <radius>0.045</radius>
          </cylinder>
        </geometry>
      </visual>
      <visual name='base_link_fixed_joint_lump__Upper_Right_Crossbar_visual_22'>
        <pose>0.185 0.12 0 0 -0 0</pose>
        <geometry>
          <box>
            <size>0.015 0.41 0.015</size>
          </box>
        </geometry>
      </visual>
      <visual name='base_link_fixed_joint_lump__Thruster_Vert_Right_visual_23'>
        <pose>0.23 0.13 0 0 -0 0</pose>
        <geometry>
          <cylinder>
            <length>0.05</length>
            <radius>0.045</radius>
          </cylinder>
        </geometry>
      </visual>
      <visual name='base_link_fixed_joint_lump__Right_Post_visual_24'>
        <pose>0.185 0 -0.1 0 -0 0</pose>
        <geometry>
          <box>
            <size>0.015 0.015 0.2</size>
          </box>
        </geometry>
      </visual>
      <visual name='base_link_fixed_joint_lump__Thruster_Back_Right_visual_25'>
        <pose>0.185 0.33 -0.045 1.57 -0 0.77</pose>
        <geometry>
          <cylinder>
            <length>0.05</length>
            <radius>0.045</radius>
          </cylinder>
        </geometry>
      </visual>
      <visual name='base_link_fixed_joint_lump__Thruster_Front_Right_visual_26'>
        <pose>0.185 -0.06 -0.045 1.57 -0 0.77</pose>
        <geometry>
          <cylinder>
            <length>0.05</length>
            <radius>0.045</radius>
          </cylinder>
        </geometry>
      </visual>
      <visual name='base_link_fixed_joint_lump__MEH_visual_27'>
        <pose>0 -0.055 0.04 0 -0 0</pose>
        <geometry>
          <box>
            <size>0.16 0.11 0.16</size>
          </box>
        </geometry>
      </visual>
    </link>
    <joint name='Front_Gripper' type='prismatic'>
      <pose relative_to='base_link'>0.1675 -0.14 -0.125 0 -0 0</pose>
      <parent>base_link</parent>
      <child>HGripper_Finger_Mobile</child>
      <axis>
        <xyz>1 0 0</xyz>
        <limit>
          <lower>-0.15</lower>
          <upper>0</upper>
          <effort>1000</effort>
          <velocity>0.5</velocity>
        </limit>
        <dynamics>
          <spring_reference>0</spring_reference>
          <spring_stiffness>0</spring_stiffness>
        </dynamics>
      </axis>
    </joint>
    <link name='HGripper_Finger_Mobile'>
      <pose relative_to='Front_Gripper'>0 0 0 0 -0 0</pose>
      <inertial>
        <pose>0 -0.05 0 0 -0 0</pose>
        <mass>0.034</mass>
        <inertia>
          <ixx>2.89708e-05</ixx>
          <ixy>0</ixy>
          <ixz>0</ixz>
          <iyy>1.275e-06</iyy>
          <iyz>0</iyz>
          <izz>2.89708e-05</izz>
        </inertia>
      </inertial>
      <collision name='HGripper_Finger_Mobile_collision'>
        <pose>0 -0.05 0 0 -0 0</pose>
        <geometry>
          <box>
            <size>0.015 0.1 0.015</size>
          </box>
        </geometry>
      </collision>
      <visual name='HGripper_Finger_Mobile_visual'>
        <pose>0 -0.05 0 0 -0 0</pose>
        <geometry>
          <box>
            <size>0.015 0.1 0.015</size>
          </box>
        </geometry>
      </visual>
    </link>
    <joint name='Bottom_Gripper' type='prismatic'>
      <pose relative_to='base_link'>0.075 0.21 -0.09 0 -0 0</pose>
      <parent>base_link</parent>
      <child>VGripper_Finger_Mobile</child>
      <axis>
        <xyz>1 0 0</xyz>
        <limit>
          <lower>-0.15</lower>
          <upper>0</upper>
          <effort>1000</effort>
          <velocity>0.5</velocity>
        </limit>
        <dynamics>
          <spring_reference>0</spring_reference>
          <spring_stiffness>0</spring_stiffness>
        </dynamics>
      </axis>
    </joint>
    <link name='VGripper_Finger_Mobile'>
      <pose relative_to='Bottom_Gripper'>0 0 0 0 -0 0</pose>
      <inertial>
        <pose>0 0 -0.05 0 -0 0</pose>
        <mass>0.034</mass>
        <inertia>
          <ixx>2.89708e-05</ixx>
          <ixy>0</ixy>
          <ixz>0</ixz>
          <iyy>2.89708e-05</iyy>
          <iyz>0</iyz>
          <izz>1.275e-06</izz>
        </inertia>
      </inertial>
      <collision name='VGripper_Finger_Mobile_collision'>
        <pose>0 0 -0.05 0 -0 0</pose>
        <geometry>
          <box>
            <size>0.015 0.015 0.1</size>
          </box>
        </geometry>
      </collision>
      <visual name='VGripper_Finger_Mobile_visual'>
        <pose>0 0 -0.05 0 -0 0</pose>
        <geometry>
          <box>
            <size>0.015 0.015 0.1</size>
          </box>
        </geometry>
      </visual>
    </link>
  </model>
</sdf>
